[2023-11-26 19:42:56,547: WARNING/MainProcess] No hostname was supplied. Reverting to default 'localhost'
[2023-11-26 19:42:56,562: WARNING/MainProcess] C:\PROJECTS\django-tutorials\course\chapter-5\notification-app\venv\lib\site-packages\celery\worker\consumer\consumer.py:507: CPendingDeprecationWarning: The broker_connection_retry configuration setting will no longer determine
whether broker connection retries are made during startup in Celery 6.0 and above.
If you wish to retain the existing behavior for retrying connections on startup,
you should set broker_connection_retry_on_startup to True.
  warnings.warn(

[2023-11-26 19:42:56,578: WARNING/MainProcess] C:\PROJECTS\django-tutorials\course\chapter-5\notification-app\venv\lib\site-packages\celery\worker\consumer\consumer.py:507: CPendingDeprecationWarning: The broker_connection_retry configuration setting will no longer determine
whether broker connection retries are made during startup in Celery 6.0 and above.
If you wish to retain the existing behavior for retrying connections on startup,
you should set broker_connection_retry_on_startup to True.
  warnings.warn(

[2023-11-26 19:42:56,602: WARNING/MainProcess] No hostname was supplied. Reverting to default 'localhost'
[2023-11-26 19:43:20,207: WARNING/MainProcess] No hostname was supplied. Reverting to default 'localhost'
[2023-11-26 19:43:20,223: WARNING/MainProcess] C:\PROJECTS\django-tutorials\course\chapter-5\notification-app\venv\lib\site-packages\celery\worker\consumer\consumer.py:507: CPendingDeprecationWarning: The broker_connection_retry configuration setting will no longer determine
whether broker connection retries are made during startup in Celery 6.0 and above.
If you wish to retain the existing behavior for retrying connections on startup,
you should set broker_connection_retry_on_startup to True.
  warnings.warn(

[2023-11-26 19:43:20,233: WARNING/MainProcess] C:\PROJECTS\django-tutorials\course\chapter-5\notification-app\venv\lib\site-packages\celery\worker\consumer\consumer.py:507: CPendingDeprecationWarning: The broker_connection_retry configuration setting will no longer determine
whether broker connection retries are made during startup in Celery 6.0 and above.
If you wish to retain the existing behavior for retrying connections on startup,
you should set broker_connection_retry_on_startup to True.
  warnings.warn(

[2023-11-26 19:43:20,260: WARNING/MainProcess] No hostname was supplied. Reverting to default 'localhost'
[2023-11-26 19:44:13,078: WARNING/MainProcess] Request: <Context: {'lang': 'py', 'task': 'core.celery.debug_task', 'id': 'cb2565c4-cc2a-4872-88c1-9f66c83b5b0a', 'shadow': None, 'eta': None, 'expires': None, 'group': None, 'group_index': None, 'retries': 0, 'timelimit': [None, None], 'root_id': 'cb2565c4-cc2a-4872-88c1-9f66c83b5b0a', 'parent_id': None, 'argsrepr': '()', 'kwargsrepr': '{}', 'origin': 'gen8904@Abdurasuloff', 'ignore_result': True, 'replaced_task_nesting': 0, 'stamped_headers': None, 'stamps': {}, 'properties': {'content_type': 'application/json', 'content_encoding': 'utf-8', 'application_headers': {'lang': 'py', 'task': 'core.celery.debug_task', 'id': 'cb2565c4-cc2a-4872-88c1-9f66c83b5b0a', 'shadow': None, 'eta': None, 'expires': None, 'group': None, 'group_index': None, 'retries': 0, 'timelimit': [None, None], 'root_id': 'cb2565c4-cc2a-4872-88c1-9f66c83b5b0a', 'parent_id': None, 'argsrepr': '()', 'kwargsrepr': '{}', 'origin': 'gen8904@Abdurasuloff', 'ignore_result': True, 'replaced_task_nesting': 0, 'stamped_headers': None, 'stamps': {}}, 'delivery_mode': 2, 'priority': 0, 'correlation_id': 'cb2565c4-cc2a-4872-88c1-9f66c83b5b0a', 'reply_to': 'eafce7a2-bc45-323b-a8f4-c738491a6176'}, 'reply_to': 'eafce7a2-bc45-323b-a8f4-c738491a6176', 'correlation_id': 'cb2565c4-cc2a-4872-88c1-9f66c83b5b0a', 'hostname': 'celery@Abdurasuloff', 'delivery_info': {'exchange': '', 'routing_key': 'celery', 'priority': 0, 'redelivered': False}, 'args': [], 'kwargs': {}, 'is_eager': False, 'callbacks': None, 'errbacks': None, 'chain': None, 'chord': None, 'called_directly': False, 'headers': None, '_protected': 1}>
[2023-11-26 19:44:32,659: CRITICAL/MainProcess] Unrecoverable error: RuntimeError("reentrant call inside <_io.BufferedWriter name='<stderr>'>")
Traceback (most recent call last):
  File "C:\PROJECTS\django-tutorials\course\chapter-5\notification-app\venv\lib\site-packages\amqp\transport.py", line 629, in _read
    s = recv(n - len(rbuf))
TimeoutError: timed out

During handling of the above exception, another exception occurred:

Traceback (most recent call last):
  File "C:\PROJECTS\django-tutorials\course\chapter-5\notification-app\venv\lib\site-packages\celery\worker\worker.py", line 202, in start
    self.blueprint.start(self)
  File "C:\PROJECTS\django-tutorials\course\chapter-5\notification-app\venv\lib\site-packages\celery\bootsteps.py", line 116, in start
    step.start(parent)
  File "C:\PROJECTS\django-tutorials\course\chapter-5\notification-app\venv\lib\site-packages\celery\bootsteps.py", line 365, in start
    return self.obj.start()
  File "C:\PROJECTS\django-tutorials\course\chapter-5\notification-app\venv\lib\site-packages\celery\worker\consumer\consumer.py", line 340, in start
    blueprint.start(self)
  File "C:\PROJECTS\django-tutorials\course\chapter-5\notification-app\venv\lib\site-packages\celery\bootsteps.py", line 116, in start
    step.start(parent)
  File "C:\PROJECTS\django-tutorials\course\chapter-5\notification-app\venv\lib\site-packages\celery\worker\consumer\consumer.py", line 742, in start
    c.loop(*c.loop_args())
  File "C:\PROJECTS\django-tutorials\course\chapter-5\notification-app\venv\lib\site-packages\celery\worker\loops.py", line 130, in synloop
    connection.drain_events(timeout=2.0)
  File "C:\PROJECTS\django-tutorials\course\chapter-5\notification-app\venv\lib\site-packages\kombu\connection.py", line 341, in drain_events
    return self.transport.drain_events(self.connection, **kwargs)
  File "C:\PROJECTS\django-tutorials\course\chapter-5\notification-app\venv\lib\site-packages\kombu\transport\pyamqp.py", line 171, in drain_events
    return connection.drain_events(**kwargs)
  File "C:\PROJECTS\django-tutorials\course\chapter-5\notification-app\venv\lib\site-packages\amqp\connection.py", line 526, in drain_events
    while not self.blocking_read(timeout):
  File "C:\PROJECTS\django-tutorials\course\chapter-5\notification-app\venv\lib\site-packages\amqp\connection.py", line 531, in blocking_read
    frame = self.transport.read_frame()
  File "C:\PROJECTS\django-tutorials\course\chapter-5\notification-app\venv\lib\site-packages\amqp\transport.py", line 294, in read_frame
    frame_header = read(7, True)
  File "C:\PROJECTS\django-tutorials\course\chapter-5\notification-app\venv\lib\site-packages\amqp\transport.py", line 629, in _read
    s = recv(n - len(rbuf))
  File "C:\PROJECTS\django-tutorials\course\chapter-5\notification-app\venv\lib\site-packages\celery\apps\worker.py", line 288, in _handle_request
    callback(worker)
  File "C:\PROJECTS\django-tutorials\course\chapter-5\notification-app\venv\lib\site-packages\celery\apps\worker.py", line 320, in on_SIGINT
    safe_say('worker: Hitting Ctrl+C again will terminate all running tasks!')
  File "C:\PROJECTS\django-tutorials\course\chapter-5\notification-app\venv\lib\site-packages\celery\apps\worker.py", line 81, in safe_say
    print(f'\n{msg}', file=sys.__stderr__, flush=True)
  File "C:\PROJECTS\django-tutorials\course\chapter-5\notification-app\venv\lib\site-packages\celery\apps\worker.py", line 288, in _handle_request
    callback(worker)
  File "C:\PROJECTS\django-tutorials\course\chapter-5\notification-app\venv\lib\site-packages\celery\apps\worker.py", line 320, in on_SIGINT
    safe_say('worker: Hitting Ctrl+C again will terminate all running tasks!')
  File "C:\PROJECTS\django-tutorials\course\chapter-5\notification-app\venv\lib\site-packages\celery\apps\worker.py", line 81, in safe_say
    print(f'\n{msg}', file=sys.__stderr__, flush=True)
RuntimeError: reentrant call inside <_io.BufferedWriter name='<stderr>'>
[2023-11-26 19:44:44,700: WARNING/MainProcess] No hostname was supplied. Reverting to default 'localhost'
[2023-11-26 19:44:44,716: WARNING/MainProcess] C:\PROJECTS\django-tutorials\course\chapter-5\notification-app\venv\lib\site-packages\celery\worker\consumer\consumer.py:507: CPendingDeprecationWarning: The broker_connection_retry configuration setting will no longer determine
whether broker connection retries are made during startup in Celery 6.0 and above.
If you wish to retain the existing behavior for retrying connections on startup,
you should set broker_connection_retry_on_startup to True.
  warnings.warn(

[2023-11-26 19:44:44,726: WARNING/MainProcess] C:\PROJECTS\django-tutorials\course\chapter-5\notification-app\venv\lib\site-packages\celery\worker\consumer\consumer.py:507: CPendingDeprecationWarning: The broker_connection_retry configuration setting will no longer determine
whether broker connection retries are made during startup in Celery 6.0 and above.
If you wish to retain the existing behavior for retrying connections on startup,
you should set broker_connection_retry_on_startup to True.
  warnings.warn(

[2023-11-26 19:44:44,741: WARNING/MainProcess] No hostname was supplied. Reverting to default 'localhost'
[2023-11-26 19:44:56,195: WARNING/MainProcess] No hostname was supplied. Reverting to default 'localhost'
[2023-11-26 19:44:56,292: WARNING/MainProcess] C:\PROJECTS\django-tutorials\course\chapter-5\notification-app\venv\lib\site-packages\celery\worker\consumer\consumer.py:507: CPendingDeprecationWarning: The broker_connection_retry configuration setting will no longer determine
whether broker connection retries are made during startup in Celery 6.0 and above.
If you wish to retain the existing behavior for retrying connections on startup,
you should set broker_connection_retry_on_startup to True.
  warnings.warn(

[2023-11-26 19:44:56,315: WARNING/MainProcess] C:\PROJECTS\django-tutorials\course\chapter-5\notification-app\venv\lib\site-packages\celery\worker\consumer\consumer.py:507: CPendingDeprecationWarning: The broker_connection_retry configuration setting will no longer determine
whether broker connection retries are made during startup in Celery 6.0 and above.
If you wish to retain the existing behavior for retrying connections on startup,
you should set broker_connection_retry_on_startup to True.
  warnings.warn(

[2023-11-26 19:44:56,355: WARNING/MainProcess] No hostname was supplied. Reverting to default 'localhost'
[2023-11-26 19:45:56,418: WARNING/MainProcess] No hostname was supplied. Reverting to default 'localhost'
[2023-11-26 19:45:56,538: WARNING/MainProcess] C:\PROJECTS\django-tutorials\course\chapter-5\notification-app\venv\lib\site-packages\celery\worker\consumer\consumer.py:507: CPendingDeprecationWarning: The broker_connection_retry configuration setting will no longer determine
whether broker connection retries are made during startup in Celery 6.0 and above.
If you wish to retain the existing behavior for retrying connections on startup,
you should set broker_connection_retry_on_startup to True.
  warnings.warn(

[2023-11-26 19:45:56,556: WARNING/MainProcess] C:\PROJECTS\django-tutorials\course\chapter-5\notification-app\venv\lib\site-packages\celery\worker\consumer\consumer.py:507: CPendingDeprecationWarning: The broker_connection_retry configuration setting will no longer determine
whether broker connection retries are made during startup in Celery 6.0 and above.
If you wish to retain the existing behavior for retrying connections on startup,
you should set broker_connection_retry_on_startup to True.
  warnings.warn(

[2023-11-26 19:45:56,599: WARNING/MainProcess] No hostname was supplied. Reverting to default 'localhost'
[2023-11-26 19:46:04,345: WARNING/MainProcess] consumer: Connection to broker lost. Trying to re-establish the connection...
Traceback (most recent call last):
  File "C:\PROJECTS\django-tutorials\course\chapter-5\notification-app\venv\lib\site-packages\celery\worker\consumer\consumer.py", line 340, in start
    blueprint.start(self)
  File "C:\PROJECTS\django-tutorials\course\chapter-5\notification-app\venv\lib\site-packages\celery\bootsteps.py", line 116, in start
    step.start(parent)
  File "C:\PROJECTS\django-tutorials\course\chapter-5\notification-app\venv\lib\site-packages\celery\worker\consumer\consumer.py", line 742, in start
    c.loop(*c.loop_args())
  File "C:\PROJECTS\django-tutorials\course\chapter-5\notification-app\venv\lib\site-packages\celery\worker\loops.py", line 130, in synloop
    connection.drain_events(timeout=2.0)
  File "C:\PROJECTS\django-tutorials\course\chapter-5\notification-app\venv\lib\site-packages\kombu\connection.py", line 341, in drain_events
    return self.transport.drain_events(self.connection, **kwargs)
  File "C:\PROJECTS\django-tutorials\course\chapter-5\notification-app\venv\lib\site-packages\kombu\transport\pyamqp.py", line 171, in drain_events
    return connection.drain_events(**kwargs)
  File "C:\PROJECTS\django-tutorials\course\chapter-5\notification-app\venv\lib\site-packages\amqp\connection.py", line 526, in drain_events
    while not self.blocking_read(timeout):
  File "C:\PROJECTS\django-tutorials\course\chapter-5\notification-app\venv\lib\site-packages\amqp\connection.py", line 532, in blocking_read
    return self.on_inbound_frame(frame)
  File "C:\PROJECTS\django-tutorials\course\chapter-5\notification-app\venv\lib\site-packages\amqp\method_framing.py", line 53, in on_frame
    callback(channel, method_sig, buf, None)
  File "C:\PROJECTS\django-tutorials\course\chapter-5\notification-app\venv\lib\site-packages\amqp\connection.py", line 538, in on_inbound_method
    return self.channels[channel_id].dispatch_method(
  File "C:\PROJECTS\django-tutorials\course\chapter-5\notification-app\venv\lib\site-packages\amqp\abstract_channel.py", line 156, in dispatch_method
    listener(*args)
  File "C:\PROJECTS\django-tutorials\course\chapter-5\notification-app\venv\lib\site-packages\amqp\connection.py", line 668, in _on_close
    raise error_for_code(reply_code, reply_text,
amqp.exceptions.ConnectionForced: (0, 0): (320) CONNECTION_FORCED - broker forced connection closure with reason 'shutdown'
[2023-11-26 19:46:04,349: WARNING/MainProcess] C:\PROJECTS\django-tutorials\course\chapter-5\notification-app\venv\lib\site-packages\celery\worker\consumer\consumer.py:391: CPendingDeprecationWarning: 
In Celery 5.1 we introduced an optional breaking change which
on connection loss cancels all currently executed tasks with late acknowledgement enabled.
These tasks cannot be acknowledged as the connection is gone, and the tasks are automatically redelivered
back to the queue. You can enable this behavior using the worker_cancel_long_running_tasks_on_connection_loss
setting. In Celery 5.1 it is set to False by default. The setting will be set to True by default in Celery 6.0.

  warnings.warn(CANCEL_TASKS_BY_DEFAULT, CPendingDeprecationWarning)

[2023-11-26 19:46:04,354: WARNING/MainProcess] C:\PROJECTS\django-tutorials\course\chapter-5\notification-app\venv\lib\site-packages\celery\worker\consumer\consumer.py:507: CPendingDeprecationWarning: The broker_connection_retry configuration setting will no longer determine
whether broker connection retries are made during startup in Celery 6.0 and above.
If you wish to retain the existing behavior for retrying connections on startup,
you should set broker_connection_retry_on_startup to True.
  warnings.warn(

[2023-11-26 19:46:04,359: ERROR/MainProcess] consumer: Cannot connect to amqp://guest:**@127.0.0.1:5672//: Server unexpectedly closed connection.
Trying again in 2.00 seconds... (1/100)

[2023-11-26 19:46:06,373: ERROR/MainProcess] consumer: Cannot connect to amqp://guest:**@127.0.0.1:5672//: Server unexpectedly closed connection.
Trying again in 4.00 seconds... (2/100)

[2023-11-26 19:46:10,412: ERROR/MainProcess] consumer: Cannot connect to amqp://guest:**@127.0.0.1:5672//: Server unexpectedly closed connection.
Trying again in 6.00 seconds... (3/100)

[2023-11-26 19:46:26,224: WARNING/MainProcess] No hostname was supplied. Reverting to default 'localhost'
[2023-11-26 19:46:26,321: WARNING/MainProcess] C:\PROJECTS\django-tutorials\course\chapter-5\notification-app\venv\lib\site-packages\celery\worker\consumer\consumer.py:507: CPendingDeprecationWarning: The broker_connection_retry configuration setting will no longer determine
whether broker connection retries are made during startup in Celery 6.0 and above.
If you wish to retain the existing behavior for retrying connections on startup,
you should set broker_connection_retry_on_startup to True.
  warnings.warn(

[2023-11-26 19:46:28,338: ERROR/MainProcess] consumer: Cannot connect to amqp://guest:**@127.0.0.1:5672//: [WinError 10061] No connection could be made because the target machine actively refused it.
Trying again in 2.00 seconds... (1/100)

[2023-11-26 19:46:32,397: ERROR/MainProcess] consumer: Cannot connect to amqp://guest:**@127.0.0.1:5672//: [WinError 10061] No connection could be made because the target machine actively refused it.
Trying again in 4.00 seconds... (2/100)

[2023-11-26 19:46:38,494: ERROR/MainProcess] consumer: Cannot connect to amqp://guest:**@127.0.0.1:5672//: [WinError 10061] No connection could be made because the target machine actively refused it.
Trying again in 6.00 seconds... (3/100)

[2023-11-26 19:46:46,595: ERROR/MainProcess] consumer: Cannot connect to amqp://guest:**@127.0.0.1:5672//: [WinError 10061] No connection could be made because the target machine actively refused it.
Trying again in 8.00 seconds... (4/100)

[2023-11-26 19:46:56,661: ERROR/MainProcess] consumer: Cannot connect to amqp://guest:**@127.0.0.1:5672//: [WinError 10061] No connection could be made because the target machine actively refused it.
Trying again in 10.00 seconds... (5/100)

[2023-11-26 19:47:07,803: ERROR/MainProcess] consumer: Cannot connect to amqp://guest:**@127.0.0.1:5672//: Server unexpectedly closed connection.
Trying again in 12.00 seconds... (6/100)

[2023-11-26 19:47:19,918: WARNING/MainProcess] C:\PROJECTS\django-tutorials\course\chapter-5\notification-app\venv\lib\site-packages\celery\worker\consumer\consumer.py:507: CPendingDeprecationWarning: The broker_connection_retry configuration setting will no longer determine
whether broker connection retries are made during startup in Celery 6.0 and above.
If you wish to retain the existing behavior for retrying connections on startup,
you should set broker_connection_retry_on_startup to True.
  warnings.warn(

[2023-11-26 19:47:19,940: WARNING/MainProcess] No hostname was supplied. Reverting to default 'localhost'
[2023-11-26 19:48:16,402: WARNING/MainProcess] No hostname was supplied. Reverting to default 'localhost'
[2023-11-26 19:48:16,498: WARNING/MainProcess] C:\PROJECTS\django-tutorials\course\chapter-5\notification-app\venv\lib\site-packages\celery\worker\consumer\consumer.py:507: CPendingDeprecationWarning: The broker_connection_retry configuration setting will no longer determine
whether broker connection retries are made during startup in Celery 6.0 and above.
If you wish to retain the existing behavior for retrying connections on startup,
you should set broker_connection_retry_on_startup to True.
  warnings.warn(

[2023-11-26 19:48:16,544: WARNING/MainProcess] C:\PROJECTS\django-tutorials\course\chapter-5\notification-app\venv\lib\site-packages\celery\worker\consumer\consumer.py:507: CPendingDeprecationWarning: The broker_connection_retry configuration setting will no longer determine
whether broker connection retries are made during startup in Celery 6.0 and above.
If you wish to retain the existing behavior for retrying connections on startup,
you should set broker_connection_retry_on_startup to True.
  warnings.warn(

[2023-11-26 19:48:16,589: WARNING/MainProcess] No hostname was supplied. Reverting to default 'localhost'
[2023-11-26 19:48:35,834: WARNING/MainProcess] consumer: Connection to broker lost. Trying to re-establish the connection...
Traceback (most recent call last):
  File "C:\PROJECTS\django-tutorials\course\chapter-5\notification-app\venv\lib\site-packages\celery\worker\consumer\consumer.py", line 340, in start
    blueprint.start(self)
  File "C:\PROJECTS\django-tutorials\course\chapter-5\notification-app\venv\lib\site-packages\celery\bootsteps.py", line 116, in start
    step.start(parent)
  File "C:\PROJECTS\django-tutorials\course\chapter-5\notification-app\venv\lib\site-packages\celery\worker\consumer\consumer.py", line 742, in start
    c.loop(*c.loop_args())
  File "C:\PROJECTS\django-tutorials\course\chapter-5\notification-app\venv\lib\site-packages\celery\worker\loops.py", line 130, in synloop
    connection.drain_events(timeout=2.0)
  File "C:\PROJECTS\django-tutorials\course\chapter-5\notification-app\venv\lib\site-packages\kombu\connection.py", line 341, in drain_events
    return self.transport.drain_events(self.connection, **kwargs)
  File "C:\PROJECTS\django-tutorials\course\chapter-5\notification-app\venv\lib\site-packages\kombu\transport\pyamqp.py", line 171, in drain_events
    return connection.drain_events(**kwargs)
  File "C:\PROJECTS\django-tutorials\course\chapter-5\notification-app\venv\lib\site-packages\amqp\connection.py", line 526, in drain_events
    while not self.blocking_read(timeout):
  File "C:\PROJECTS\django-tutorials\course\chapter-5\notification-app\venv\lib\site-packages\amqp\connection.py", line 532, in blocking_read
    return self.on_inbound_frame(frame)
  File "C:\PROJECTS\django-tutorials\course\chapter-5\notification-app\venv\lib\site-packages\amqp\method_framing.py", line 53, in on_frame
    callback(channel, method_sig, buf, None)
  File "C:\PROJECTS\django-tutorials\course\chapter-5\notification-app\venv\lib\site-packages\amqp\connection.py", line 538, in on_inbound_method
    return self.channels[channel_id].dispatch_method(
  File "C:\PROJECTS\django-tutorials\course\chapter-5\notification-app\venv\lib\site-packages\amqp\abstract_channel.py", line 156, in dispatch_method
    listener(*args)
  File "C:\PROJECTS\django-tutorials\course\chapter-5\notification-app\venv\lib\site-packages\amqp\connection.py", line 668, in _on_close
    raise error_for_code(reply_code, reply_text,
amqp.exceptions.ConnectionForced: (0, 0): (320) CONNECTION_FORCED - broker forced connection closure with reason 'shutdown'
[2023-11-26 19:48:35,838: WARNING/MainProcess] C:\PROJECTS\django-tutorials\course\chapter-5\notification-app\venv\lib\site-packages\celery\worker\consumer\consumer.py:391: CPendingDeprecationWarning: 
In Celery 5.1 we introduced an optional breaking change which
on connection loss cancels all currently executed tasks with late acknowledgement enabled.
These tasks cannot be acknowledged as the connection is gone, and the tasks are automatically redelivered
back to the queue. You can enable this behavior using the worker_cancel_long_running_tasks_on_connection_loss
setting. In Celery 5.1 it is set to False by default. The setting will be set to True by default in Celery 6.0.

  warnings.warn(CANCEL_TASKS_BY_DEFAULT, CPendingDeprecationWarning)

[2023-11-26 19:48:35,841: WARNING/MainProcess] C:\PROJECTS\django-tutorials\course\chapter-5\notification-app\venv\lib\site-packages\celery\worker\consumer\consumer.py:507: CPendingDeprecationWarning: The broker_connection_retry configuration setting will no longer determine
whether broker connection retries are made during startup in Celery 6.0 and above.
If you wish to retain the existing behavior for retrying connections on startup,
you should set broker_connection_retry_on_startup to True.
  warnings.warn(

[2023-11-26 19:48:35,843: ERROR/MainProcess] consumer: Cannot connect to amqp://guest:**@127.0.0.1:5672//: Server unexpectedly closed connection.
Trying again in 2.00 seconds... (1/100)

[2023-11-26 19:48:37,877: ERROR/MainProcess] consumer: Cannot connect to amqp://guest:**@127.0.0.1:5672//: Server unexpectedly closed connection.
Trying again in 4.00 seconds... (2/100)

[2023-11-26 19:48:41,921: ERROR/MainProcess] consumer: Cannot connect to amqp://guest:**@127.0.0.1:5672//: Server unexpectedly closed connection.
Trying again in 6.00 seconds... (3/100)

[2023-11-26 19:48:53,280: WARNING/MainProcess] No hostname was supplied. Reverting to default 'localhost'
[2023-11-26 19:48:53,384: WARNING/MainProcess] C:\PROJECTS\django-tutorials\course\chapter-5\notification-app\venv\lib\site-packages\celery\worker\consumer\consumer.py:507: CPendingDeprecationWarning: The broker_connection_retry configuration setting will no longer determine
whether broker connection retries are made during startup in Celery 6.0 and above.
If you wish to retain the existing behavior for retrying connections on startup,
you should set broker_connection_retry_on_startup to True.
  warnings.warn(

[2023-11-26 19:48:55,420: ERROR/MainProcess] consumer: Cannot connect to amqp://guest:**@127.0.0.1:5672//: [WinError 10061] No connection could be made because the target machine actively refused it.
Trying again in 2.00 seconds... (1/100)

[2023-11-26 19:48:59,494: ERROR/MainProcess] consumer: Cannot connect to amqp://guest:**@127.0.0.1:5672//: [WinError 10061] No connection could be made because the target machine actively refused it.
Trying again in 4.00 seconds... (2/100)

[2023-11-26 19:49:05,582: ERROR/MainProcess] consumer: Cannot connect to amqp://guest:**@127.0.0.1:5672//: [WinError 10061] No connection could be made because the target machine actively refused it.
Trying again in 6.00 seconds... (3/100)

[2023-11-26 19:49:20,650: WARNING/MainProcess] No hostname was supplied. Reverting to default 'localhost'
[2023-11-26 19:49:20,737: WARNING/MainProcess] C:\PROJECTS\django-tutorials\course\chapter-5\notification-app\venv\lib\site-packages\celery\worker\consumer\consumer.py:507: CPendingDeprecationWarning: The broker_connection_retry configuration setting will no longer determine
whether broker connection retries are made during startup in Celery 6.0 and above.
If you wish to retain the existing behavior for retrying connections on startup,
you should set broker_connection_retry_on_startup to True.
  warnings.warn(

[2023-11-26 19:49:22,764: ERROR/MainProcess] consumer: Cannot connect to amqp://guest:**@127.0.0.1:5672//: [WinError 10061] No connection could be made because the target machine actively refused it.
Trying again in 2.00 seconds... (1/100)

[2023-11-26 19:49:26,833: ERROR/MainProcess] consumer: Cannot connect to amqp://guest:**@127.0.0.1:5672//: [WinError 10061] No connection could be made because the target machine actively refused it.
Trying again in 4.00 seconds... (2/100)

[2023-12-05 02:10:41,189: WARNING/MainProcess] No hostname was supplied. Reverting to default 'localhost'
[2023-12-05 02:10:41,208: WARNING/MainProcess] C:\PROJECTS\django-tutorials\course\chapter-5\notification-app\venv\lib\site-packages\celery\worker\consumer\consumer.py:507: CPendingDeprecationWarning: The broker_connection_retry configuration setting will no longer determine
whether broker connection retries are made during startup in Celery 6.0 and above.
If you wish to retain the existing behavior for retrying connections on startup,
you should set broker_connection_retry_on_startup to True.
  warnings.warn(

[2023-12-05 02:10:41,218: WARNING/MainProcess] C:\PROJECTS\django-tutorials\course\chapter-5\notification-app\venv\lib\site-packages\celery\worker\consumer\consumer.py:507: CPendingDeprecationWarning: The broker_connection_retry configuration setting will no longer determine
whether broker connection retries are made during startup in Celery 6.0 and above.
If you wish to retain the existing behavior for retrying connections on startup,
you should set broker_connection_retry_on_startup to True.
  warnings.warn(

[2023-12-05 02:10:41,260: WARNING/MainProcess] No hostname was supplied. Reverting to default 'localhost'
